ERROR:tornado.access:500 GET /fetch_image (::1) 357.61ms
ERROR:tornado.access:500 GET /fetch_image (::1) 184.10ms
ERROR:tornado.access:500 GET /crypto-detector (::1) 221.75ms
ERROR:tornado.access:500 GET /crypto-detector (::1) 1031.40ms
ERROR:tornado.access:500 POST /classify (::1) 3232.99ms
ERROR:tornado.application:Uncaught exception
Traceback (most recent call last):
  File "C:\Users\intern.nlshuong\AppData\Local\Programs\Python\Python311\Lib\site-packages\tornado\http1connection.py", line 276, in _read_message
    delegate.finish()
  File "C:\Users\intern.nlshuong\AppData\Local\Programs\Python\Python311\Lib\site-packages\tornado\routing.py", line 268, in finish
    self.delegate.finish()
  File "C:\Users\intern.nlshuong\AppData\Local\Programs\Python\Python311\Lib\site-packages\tornado\web.py", line 2395, in finish
    self.execute()
  File "C:\Users\intern.nlshuong\AppData\Local\Programs\Python\Python311\Lib\site-packages\tornado\web.py", line 2417, in execute
    self.handler = self.handler_class(
                   ^^^^^^^^^^^^^^^^^^^
  File "C:\Users\intern.nlshuong\AppData\Local\Programs\Python\Python311\Lib\site-packages\tornado\web.py", line 238, in __init__
    self.initialize(**kwargs)  # type: ignore
    ^^^^^^^^^^^^^^^^^^^^^^^^^
TypeError: ImageClassificationHandler.initialize() missing 1 required positional argument: 'api_connector'
ERROR:tornado.application:Uncaught exception
Traceback (most recent call last):
  File "C:\Users\intern.nlshuong\AppData\Local\Programs\Python\Python311\Lib\site-packages\tornado\http1connection.py", line 276, in _read_message
    delegate.finish()
  File "C:\Users\intern.nlshuong\AppData\Local\Programs\Python\Python311\Lib\site-packages\tornado\routing.py", line 268, in finish
    self.delegate.finish()
  File "C:\Users\intern.nlshuong\AppData\Local\Programs\Python\Python311\Lib\site-packages\tornado\web.py", line 2395, in finish
    self.execute()
  File "C:\Users\intern.nlshuong\AppData\Local\Programs\Python\Python311\Lib\site-packages\tornado\web.py", line 2417, in execute
    self.handler = self.handler_class(
                   ^^^^^^^^^^^^^^^^^^^
  File "C:\Users\intern.nlshuong\AppData\Local\Programs\Python\Python311\Lib\site-packages\tornado\web.py", line 238, in __init__
    self.initialize(**kwargs)  # type: ignore
    ^^^^^^^^^^^^^^^^^^^^^^^^^
TypeError: ImageClassificationHandler.initialize() missing 1 required positional argument: 'api_connector'
ERROR:tornado.application:Uncaught exception
Traceback (most recent call last):
  File "C:\Users\intern.nlshuong\AppData\Local\Programs\Python\Python311\Lib\site-packages\tornado\http1connection.py", line 276, in _read_message
    delegate.finish()
  File "C:\Users\intern.nlshuong\AppData\Local\Programs\Python\Python311\Lib\site-packages\tornado\routing.py", line 268, in finish
    self.delegate.finish()
  File "C:\Users\intern.nlshuong\AppData\Local\Programs\Python\Python311\Lib\site-packages\tornado\web.py", line 2395, in finish
    self.execute()
  File "C:\Users\intern.nlshuong\AppData\Local\Programs\Python\Python311\Lib\site-packages\tornado\web.py", line 2417, in execute
    self.handler = self.handler_class(
                   ^^^^^^^^^^^^^^^^^^^
  File "C:\Users\intern.nlshuong\AppData\Local\Programs\Python\Python311\Lib\site-packages\tornado\web.py", line 238, in __init__
    self.initialize(**kwargs)  # type: ignore
    ^^^^^^^^^^^^^^^^^^^^^^^^^
TypeError: ImageClassificationHandler.initialize() missing 1 required positional argument: 'api_connector'
ERROR:tornado.application:Uncaught exception
Traceback (most recent call last):
  File "C:\Users\intern.nlshuong\AppData\Local\Programs\Python\Python311\Lib\site-packages\tornado\http1connection.py", line 276, in _read_message
    delegate.finish()
  File "C:\Users\intern.nlshuong\AppData\Local\Programs\Python\Python311\Lib\site-packages\tornado\routing.py", line 268, in finish
    self.delegate.finish()
  File "C:\Users\intern.nlshuong\AppData\Local\Programs\Python\Python311\Lib\site-packages\tornado\web.py", line 2395, in finish
    self.execute()
  File "C:\Users\intern.nlshuong\AppData\Local\Programs\Python\Python311\Lib\site-packages\tornado\web.py", line 2417, in execute
    self.handler = self.handler_class(
                   ^^^^^^^^^^^^^^^^^^^
  File "C:\Users\intern.nlshuong\AppData\Local\Programs\Python\Python311\Lib\site-packages\tornado\web.py", line 238, in __init__
    self.initialize(**kwargs)  # type: ignore
    ^^^^^^^^^^^^^^^^^^^^^^^^^
TypeError: ImageClassificationHandler.initialize() missing 1 required positional argument: 'api_connector'
ERROR:tornado.access:500 POST /classify (::1) 3267.06ms
ERROR:tornado.application:Uncaught exception
Traceback (most recent call last):
  File "C:\Users\intern.nlshuong\AppData\Local\Programs\Python\Python311\Lib\site-packages\tornado\http1connection.py", line 276, in _read_message
    delegate.finish()
  File "C:\Users\intern.nlshuong\AppData\Local\Programs\Python\Python311\Lib\site-packages\tornado\routing.py", line 268, in finish
    self.delegate.finish()
  File "C:\Users\intern.nlshuong\AppData\Local\Programs\Python\Python311\Lib\site-packages\tornado\httpserver.py", line 292, in finish
    self.request_callback(self.request)
TypeError: ApiConnector.__init__() got an unexpected keyword argument 'target_kwargs'
ERROR:tornado.application:Uncaught exception
Traceback (most recent call last):
  File "C:\Users\intern.nlshuong\AppData\Local\Programs\Python\Python311\Lib\site-packages\tornado\http1connection.py", line 276, in _read_message
    delegate.finish()
  File "C:\Users\intern.nlshuong\AppData\Local\Programs\Python\Python311\Lib\site-packages\tornado\routing.py", line 268, in finish
    self.delegate.finish()
  File "C:\Users\intern.nlshuong\AppData\Local\Programs\Python\Python311\Lib\site-packages\tornado\httpserver.py", line 292, in finish
    self.request_callback(self.request)
TypeError: ApiConnector.__init__() got an unexpected keyword argument 'target_kwargs'
ERROR:tornado.application:Uncaught exception
Traceback (most recent call last):
  File "C:\Users\intern.nlshuong\AppData\Local\Programs\Python\Python311\Lib\site-packages\tornado\http1connection.py", line 276, in _read_message
    delegate.finish()
  File "C:\Users\intern.nlshuong\AppData\Local\Programs\Python\Python311\Lib\site-packages\tornado\routing.py", line 268, in finish
    self.delegate.finish()
  File "C:\Users\intern.nlshuong\AppData\Local\Programs\Python\Python311\Lib\site-packages\tornado\httpserver.py", line 292, in finish
    self.request_callback(self.request)
TypeError: ApiConnector.__init__() got an unexpected keyword argument 'target_kwargs'
ERROR:tornado.application:Uncaught exception
Traceback (most recent call last):
  File "C:\Users\intern.nlshuong\AppData\Local\Programs\Python\Python311\Lib\site-packages\tornado\http1connection.py", line 276, in _read_message
    delegate.finish()
  File "C:\Users\intern.nlshuong\AppData\Local\Programs\Python\Python311\Lib\site-packages\tornado\routing.py", line 268, in finish
    self.delegate.finish()
  File "C:\Users\intern.nlshuong\AppData\Local\Programs\Python\Python311\Lib\site-packages\tornado\httpserver.py", line 292, in finish
    self.request_callback(self.request)
TypeError: ApiConnector.__init__() got an unexpected keyword argument 'target_kwargs'
ERROR:tornado.access:500 POST /classify (::1) 4082.57ms
ERROR:tornado.access:500 POST /classify (::1) 3374.60ms
ERROR:tornado.access:500 POST /classify (::1) 3242.16ms
